[2024-04-08T06:25:21.820+0000] {taskinstance.py:1083} INFO - Dependencies all met for <TaskInstance: our_dag_with_python_operator_v04.greet manual__2024-04-08T06:25:20.420270+00:00 [queued]>
[2024-04-08T06:25:21.829+0000] {taskinstance.py:1083} INFO - Dependencies all met for <TaskInstance: our_dag_with_python_operator_v04.greet manual__2024-04-08T06:25:20.420270+00:00 [queued]>
[2024-04-08T06:25:21.829+0000] {taskinstance.py:1279} INFO - 
--------------------------------------------------------------------------------
[2024-04-08T06:25:21.830+0000] {taskinstance.py:1280} INFO - Starting attempt 1 of 6
[2024-04-08T06:25:21.830+0000] {taskinstance.py:1281} INFO - 
--------------------------------------------------------------------------------
[2024-04-08T06:25:21.844+0000] {taskinstance.py:1300} INFO - Executing <Task(PythonOperator): greet> on 2024-04-08 06:25:20.420270+00:00
[2024-04-08T06:25:21.849+0000] {standard_task_runner.py:55} INFO - Started process 21053 to run task
[2024-04-08T06:25:21.850+0000] {standard_task_runner.py:82} INFO - Running: ['***', 'tasks', 'run', 'our_dag_with_python_operator_v04', 'greet', 'manual__2024-04-08T06:25:20.420270+00:00', '--job-id', '1511', '--raw', '--subdir', 'DAGS_FOLDER/create_dag_with_python_operator.py', '--cfg-path', '/tmp/tmpgbt55unp']
[2024-04-08T06:25:21.852+0000] {standard_task_runner.py:83} INFO - Job 1511: Subtask greet
[2024-04-08T06:25:21.904+0000] {task_command.py:388} INFO - Running <TaskInstance: our_dag_with_python_operator_v04.greet manual__2024-04-08T06:25:20.420270+00:00 [running]> on host 3dc1147ef06e
[2024-04-08T06:25:21.965+0000] {taskinstance.py:1509} INFO - Exporting the following env vars:
AIRFLOW_CTX_DAG_OWNER=jiseungmin
AIRFLOW_CTX_DAG_ID=our_dag_with_python_operator_v04
AIRFLOW_CTX_TASK_ID=greet
AIRFLOW_CTX_EXECUTION_DATE=2024-04-08T06:25:20.420270+00:00
AIRFLOW_CTX_TRY_NUMBER=1
AIRFLOW_CTX_DAG_RUN_ID=manual__2024-04-08T06:25:20.420270+00:00
[2024-04-08T06:25:21.966+0000] {taskinstance.py:1768} ERROR - Task failed with exception
Traceback (most recent call last):
  File "/home/airflow/.local/lib/python3.7/site-packages/airflow/operators/python.py", line 175, in execute
    return_value = self.execute_callable()
  File "/home/airflow/.local/lib/python3.7/site-packages/airflow/operators/python.py", line 192, in execute_callable
    return self.python_callable(*self.op_args, **self.op_kwargs)
  File "/opt/airflow/dags/create_dag_with_python_operator.py", line 12, in great
    name = ti.xoms_pull(task_ids='get_name')
AttributeError: 'TaskInstance' object has no attribute 'xoms_pull'
[2024-04-08T06:25:21.976+0000] {taskinstance.py:1323} INFO - Marking task as UP_FOR_RETRY. dag_id=our_dag_with_python_operator_v04, task_id=greet, execution_date=20240408T062520, start_date=20240408T062521, end_date=20240408T062521
[2024-04-08T06:25:21.987+0000] {standard_task_runner.py:105} ERROR - Failed to execute job 1511 for task greet ('TaskInstance' object has no attribute 'xoms_pull'; 21053)
[2024-04-08T06:25:22.023+0000] {local_task_job.py:208} INFO - Task exited with return code 1
[2024-04-08T06:25:22.037+0000] {taskinstance.py:2578} INFO - 0 downstream tasks scheduled from follow-on schedule check
